<?xml version="1.0"?>
<robot name="spider">
  <!-- Base Link (Torso) -->
  <link name="torso">
    <inertial>
      <origin xyz="0 0 0" rpy="0 0 0"/>
      <mass value="2.5"/>
      <inertia ixx="0.0083" ixy="0" ixz="0" iyy="0.0083" iyz="0" izz="0.0125"/>
    </inertial>
    <visual>
      <origin xyz="0 0 0" rpy="0 0 0"/>
      <geometry>
        <box size="0.2 0.15 0.05"/>
      </geometry>
      <material name="body_color">
        <color rgba="0.3 0.3 0.3 1"/>
      </material>
    </visual>
    <collision>
      <origin xyz="0 0 0" rpy="0 0 0"/>
      <geometry>
        <box size="0.2 0.15 0.05"/>
      </geometry>
    </collision>
  </link>

  <!-- IMU Sensor (virtual link for orientation sensing) -->
  <link name="imu_link">
    <inertial>
      <mass value="0.001"/>
      <inertia ixx="0.000001" ixy="0" ixz="0" iyy="0.000001" iyz="0" izz="0.000001"/>
    </inertial>
  </link>

  <joint name="imu_joint" type="fixed">
    <parent link="torso"/>
    <child link="imu_link"/>
    <origin xyz="0 0 0" rpy="0 0 0"/>
  </joint>

  <!-- Leg 0: Front Right -->
  <link name="coxa_0">
    <inertial>
      <origin xyz="0.025 0 0" rpy="0 0 0"/>
      <mass value="0.1"/>
      <inertia ixx="0.00005" ixy="0" ixz="0" iyy="0.00005" iyz="0" izz="0.00001"/>
    </inertial>
    <visual>
      <origin xyz="0.025 0 0" rpy="0 0 0"/>
      <geometry>
        <box size="0.05 0.02 0.02"/>
      </geometry>
      <material name="leg_color">
        <color rgba="0.6 0.3 0.1 1"/>
      </material>
    </visual>
    <collision>
      <origin xyz="0.025 0 0" rpy="0 0 0"/>
      <geometry>
        <box size="0.05 0.02 0.02"/>
      </geometry>
    </collision>
  </link>

  <joint name="coxa_0" type="revolute">
    <parent link="torso"/>
    <child link="coxa_0"/>
    <origin xyz="0.08 -0.06 0" rpy="0 0 0"/>
    <axis xyz="0 0 1"/>
    <limit lower="-0.785" upper="0.785" effort="10.0" velocity="5.0"/>
    <dynamics damping="0.5" friction="0.1"/>
  </joint>

  <link name="femur_0">
    <inertial>
      <origin xyz="0 0 -0.05" rpy="0 0 0"/>
      <mass value="0.08"/>
      <inertia ixx="0.00008" ixy="0" ixz="0" iyy="0.00008" iyz="0" izz="0.00001"/>
    </inertial>
    <visual>
      <origin xyz="0 0 -0.05" rpy="0 0 0"/>
      <geometry>
        <box size="0.015 0.015 0.10"/>
      </geometry>
      <material name="leg_color"/>
    </visual>
    <collision>
      <origin xyz="0 0 -0.05" rpy="0 0 0"/>
      <geometry>
        <box size="0.015 0.015 0.10"/>
      </geometry>
    </collision>
  </link>

  <joint name="femur_0" type="revolute">
    <parent link="coxa_0"/>
    <child link="femur_0"/>
    <origin xyz="0.05 0 0" rpy="0 0 0"/>
    <axis xyz="0 1 0"/>
    <limit lower="-1.57" upper="1.57" effort="10.0" velocity="5.0"/>
    <dynamics damping="0.5" friction="0.1"/>
  </joint>

  <link name="tibia_0">
    <inertial>
      <origin xyz="0 0 -0.06" rpy="0 0 0"/>
      <mass value="0.06"/>
      <inertia ixx="0.00007" ixy="0" ixz="0" iyy="0.00007" iyz="0" izz="0.00001"/>
    </inertial>
    <visual>
      <origin xyz="0 0 -0.06" rpy="0 0 0"/>
      <geometry>
        <box size="0.012 0.012 0.12"/>
      </geometry>
      <material name="leg_color"/>
    </visual>
    <collision>
      <origin xyz="0 0 -0.06" rpy="0 0 0"/>
      <geometry>
        <box size="0.012 0.012 0.12"/>
      </geometry>
    </collision>
  </link>

  <joint name="tibia_0" type="revolute">
    <parent link="femur_0"/>
    <child link="tibia_0"/>
    <origin xyz="0 0 -0.10" rpy="0 0 0"/>
    <axis xyz="0 1 0"/>
    <limit lower="-2.356" upper="0.0" effort="10.0" velocity="5.0"/>
    <dynamics damping="0.5" friction="0.1"/>
  </joint>

  <link name="foot_0">
    <inertial>
      <mass value="0.02"/>
      <inertia ixx="0.00001" ixy="0" ixz="0" iyy="0.00001" iyz="0" izz="0.00001"/>
    </inertial>
    <visual>
      <geometry>
        <sphere radius="0.015"/>
      </geometry>
      <material name="foot_color">
        <color rgba="0.2 0.2 0.2 1"/>
      </material>
    </visual>
    <collision>
      <geometry>
        <sphere radius="0.015"/>
      </geometry>
    </collision>
  </link>

  <joint name="foot_0" type="fixed">
    <parent link="tibia_0"/>
    <child link="foot_0"/>
    <origin xyz="0 0 -0.12" rpy="0 0 0"/>
  </joint>

  <!-- Leg 1: Front Left -->
  <link name="coxa_1">
    <inertial>
      <origin xyz="0.025 0 0" rpy="0 0 0"/>
      <mass value="0.1"/>
      <inertia ixx="0.00005" ixy="0" ixz="0" iyy="0.00005" iyz="0" izz="0.00001"/>
    </inertial>
    <visual>
      <origin xyz="0.025 0 0" rpy="0 0 0"/>
      <geometry>
        <box size="0.05 0.02 0.02"/>
      </geometry>
      <material name="leg_color"/>
    </visual>
    <collision>
      <origin xyz="0.025 0 0" rpy="0 0 0"/>
      <geometry>
        <box size="0.05 0.02 0.02"/>
      </geometry>
    </collision>
  </link>

  <joint name="coxa_1" type="revolute">
    <parent link="torso"/>
    <child link="coxa_1"/>
    <origin xyz="0.08 0.06 0" rpy="0 0 0"/>
    <axis xyz="0 0 1"/>
    <limit lower="-0.785" upper="0.785" effort="10.0" velocity="5.0"/>
    <dynamics damping="0.5" friction="0.1"/>
  </joint>

  <link name="femur_1">
    <inertial>
      <origin xyz="0 0 -0.05" rpy="0 0 0"/>
      <mass value="0.08"/>
      <inertia ixx="0.00008" ixy="0" ixz="0" iyy="0.00008" iyz="0" izz="0.00001"/>
    </inertial>
    <visual>
      <origin xyz="0 0 -0.05" rpy="0 0 0"/>
      <geometry>
        <box size="0.015 0.015 0.10"/>
      </geometry>
      <material name="leg_color"/>
    </visual>
    <collision>
      <origin xyz="0 0 -0.05" rpy="0 0 0"/>
      <geometry>
        <box size="0.015 0.015 0.10"/>
      </geometry>
    </collision>
  </link>

  <joint name="femur_1" type="revolute">
    <parent link="coxa_1"/>
    <child link="femur_1"/>
    <origin xyz="0.05 0 0" rpy="0 0 0"/>
    <axis xyz="0 1 0"/>
    <limit lower="-1.57" upper="1.57" effort="10.0" velocity="5.0"/>
    <dynamics damping="0.5" friction="0.1"/>
  </joint>

  <link name="tibia_1">
    <inertial>
      <origin xyz="0 0 -0.06" rpy="0 0 0"/>
      <mass value="0.06"/>
      <inertia ixx="0.00007" ixy="0" ixz="0" iyy="0.00007" iyz="0" izz="0.00001"/>
    </inertial>
    <visual>
      <origin xyz="0 0 -0.06" rpy="0 0 0"/>
      <geometry>
        <box size="0.012 0.012 0.12"/>
      </geometry>
      <material name="leg_color"/>
    </visual>
    <collision>
      <origin xyz="0 0 -0.06" rpy="0 0 0"/>
      <geometry>
        <box size="0.012 0.012 0.12"/>
      </geometry>
    </collision>
  </link>

  <joint name="tibia_1" type="revolute">
    <parent link="femur_1"/>
    <child link="tibia_1"/>
    <origin xyz="0 0 -0.10" rpy="0 0 0"/>
    <axis xyz="0 1 0"/>
    <limit lower="-2.356" upper="0.0" effort="10.0" velocity="5.0"/>
    <dynamics damping="0.5" friction="0.1"/>
  </joint>

  <link name="foot_1">
    <inertial>
      <mass value="0.02"/>
      <inertia ixx="0.00001" ixy="0" ixz="0" iyy="0.00001" iyz="0" izz="0.00001"/>
    </inertial>
    <visual>
      <geometry>
        <sphere radius="0.015"/>
      </geometry>
      <material name="foot_color"/>
    </visual>
    <collision>
      <geometry>
        <sphere radius="0.015"/>
      </geometry>
    </collision>
  </link>

  <joint name="foot_1" type="fixed">
    <parent link="tibia_1"/>
    <child link="foot_1"/>
    <origin xyz="0 0 -0.12" rpy="0 0 0"/>
  </joint>

  <!-- Leg 2: Mid-Front Right -->
  <link name="coxa_2">
    <inertial>
      <origin xyz="0.025 0 0" rpy="0 0 0"/>
      <mass value="0.1"/>
      <inertia ixx="0.00005" ixy="0" ixz="0" iyy="0.00005" iyz="0" izz="0.00001"/>
    </inertial>
    <visual>
      <origin xyz="0.025 0 0" rpy="0 0 0"/>
      <geometry>
        <box size="0.05 0.02 0.02"/>
      </geometry>
      <material name="leg_color"/>
    </visual>
    <collision>
      <origin xyz="0.025 0 0" rpy="0 0 0"/>
      <geometry>
        <box size="0.05 0.02 0.02"/>
      </geometry>
    </collision>
  </link>

  <joint name="coxa_2" type="revolute">
    <parent link="torso"/>
    <child link="coxa_2"/>
    <origin xyz="0.02 -0.075 0" rpy="0 0 0"/>
    <axis xyz="0 0 1"/>
    <limit lower="-0.785" upper="0.785" effort="10.0" velocity="5.0"/>
    <dynamics damping="0.5" friction="0.1"/>
  </joint>

  <link name="femur_2">
    <inertial>
      <origin xyz="0 0 -0.05" rpy="0 0 0"/>
      <mass value="0.08"/>
      <inertia ixx="0.00008" ixy="0" ixz="0" iyy="0.00008" iyz="0" izz="0.00001"/>
    </inertial>
    <visual>
      <origin xyz="0 0 -0.05" rpy="0 0 0"/>
      <geometry>
        <box size="0.015 0.015 0.10"/>
      </geometry>
      <material name="leg_color"/>
    </visual>
    <collision>
      <origin xyz="0 0 -0.05" rpy="0 0 0"/>
      <geometry>
        <box size="0.015 0.015 0.10"/>
      </geometry>
    </collision>
  </link>

  <joint name="femur_2" type="revolute">
    <parent link="coxa_2"/>
    <child link="femur_2"/>
    <origin xyz="0.05 0 0" rpy="0 0 0"/>
    <axis xyz="0 1 0"/>
    <limit lower="-1.57" upper="1.57" effort="10.0" velocity="5.0"/>
    <dynamics damping="0.5" friction="0.1"/>
  </joint>

  <link name="tibia_2">
    <inertial>
      <origin xyz="0 0 -0.06" rpy="0 0 0"/>
      <mass value="0.06"/>
      <inertia ixx="0.00007" ixy="0" ixz="0" iyy="0.00007" iyz="0" izz="0.00001"/>
    </inertial>
    <visual>
      <origin xyz="0 0 -0.06" rpy="0 0 0"/>
      <geometry>
        <box size="0.012 0.012 0.12"/>
      </geometry>
      <material name="leg_color"/>
    </visual>
    <collision>
      <origin xyz="0 0 -0.06" rpy="0 0 0"/>
      <geometry>
        <box size="0.012 0.012 0.12"/>
      </geometry>
    </collision>
  </link>

  <joint name="tibia_2" type="revolute">
    <parent link="femur_2"/>
    <child link="tibia_2"/>
    <origin xyz="0 0 -0.10" rpy="0 0 0"/>
    <axis xyz="0 1 0"/>
    <limit lower="-2.356" upper="0.0" effort="10.0" velocity="5.0"/>
    <dynamics damping="0.5" friction="0.1"/>
  </joint>

  <link name="foot_2">
    <inertial>
      <mass value="0.02"/>
      <inertia ixx="0.00001" ixy="0" ixz="0" iyy="0.00001" iyz="0" izz="0.00001"/>
    </inertial>
    <visual>
      <geometry>
        <sphere radius="0.015"/>
      </geometry>
      <material name="foot_color"/>
    </visual>
    <collision>
      <geometry>
        <sphere radius="0.015"/>
      </geometry>
    </collision>
  </link>

  <joint name="foot_2" type="fixed">
    <parent link="tibia_2"/>
    <child link="foot_2"/>
    <origin xyz="0 0 -0.12" rpy="0 0 0"/>
  </joint>

  <!-- Leg 3: Mid-Front Left -->
  <link name="coxa_3">
    <inertial>
      <origin xyz="0.025 0 0" rpy="0 0 0"/>
      <mass value="0.1"/>
      <inertia ixx="0.00005" ixy="0" ixz="0" iyy="0.00005" iyz="0" izz="0.00001"/>
    </inertial>
    <visual>
      <origin xyz="0.025 0 0" rpy="0 0 0"/>
      <geometry>
        <box size="0.05 0.02 0.02"/>
      </geometry>
      <material name="leg_color"/>
    </visual>
    <collision>
      <origin xyz="0.025 0 0" rpy="0 0 0"/>
      <geometry>
        <box size="0.05 0.02 0.02"/>
      </geometry>
    </collision>
  </link>

  <joint name="coxa_3" type="revolute">
    <parent link="torso"/>
    <child link="coxa_3"/>
    <origin xyz="0.02 0.075 0" rpy="0 0 0"/>
    <axis xyz="0 0 1"/>
    <limit lower="-0.785" upper="0.785" effort="10.0" velocity="5.0"/>
    <dynamics damping="0.5" friction="0.1"/>
  </joint>

  <link name="femur_3">
    <inertial>
      <origin xyz="0 0 -0.05" rpy="0 0 0"/>
      <mass value="0.08"/>
      <inertia ixx="0.00008" ixy="0" ixz="0" iyy="0.00008" iyz="0" izz="0.00001"/>
    </inertial>
    <visual>
      <origin xyz="0 0 -0.05" rpy="0 0 0"/>
      <geometry>
        <box size="0.015 0.015 0.10"/>
      </geometry>
      <material name="leg_color"/>
    </visual>
    <collision>
      <origin xyz="0 0 -0.05" rpy="0 0 0"/>
      <geometry>
        <box size="0.015 0.015 0.10"/>
      </geometry>
    </collision>
  </link>

  <joint name="femur_3" type="revolute">
    <parent link="coxa_3"/>
    <child link="femur_3"/>
    <origin xyz="0.05 0 0" rpy="0 0 0"/>
    <axis xyz="0 1 0"/>
    <limit lower="-1.57" upper="1.57" effort="10.0" velocity="5.0"/>
    <dynamics damping="0.5" friction="0.1"/>
  </joint>

  <link name="tibia_3">
    <inertial>
      <origin xyz="0 0 -0.06" rpy="0 0 0"/>
      <mass value="0.06"/>
      <inertia ixx="0.00007" ixy="0" ixz="0" iyy="0.00007" iyz="0" izz="0.00001"/>
    </inertial>
    <visual>
      <origin xyz="0 0 -0.06" rpy="0 0 0"/>
      <geometry>
        <box size="0.012 0.012 0.12"/>
      </geometry>
      <material name="leg_color"/>
    </visual>
    <collision>
      <origin xyz="0 0 -0.06" rpy="0 0 0"/>
      <geometry>
        <box size="0.012 0.012 0.12"/>
      </geometry>
    </collision>
  </link>

  <joint name="tibia_3" type="revolute">
    <parent link="femur_3"/>
    <child link="tibia_3"/>
    <origin xyz="0 0 -0.10" rpy="0 0 0"/>
    <axis xyz="0 1 0"/>
    <limit lower="-2.356" upper="0.0" effort="10.0" velocity="5.0"/>
    <dynamics damping="0.5" friction="0.1"/>
  </joint>

  <link name="foot_3">
    <inertial>
      <mass value="0.02"/>
      <inertia ixx="0.00001" ixy="0" ixz="0" iyy="0.00001" iyz="0" izz="0.00001"/>
    </inertial>
    <visual>
      <geometry>
        <sphere radius="0.015"/>
      </geometry>
      <material name="foot_color"/>
    </visual>
    <collision>
      <geometry>
        <sphere radius="0.015"/>
      </geometry>
    </collision>
  </link>

  <joint name="foot_3" type="fixed">
    <parent link="tibia_3"/>
    <child link="foot_3"/>
    <origin xyz="0 0 -0.12" rpy="0 0 0"/>
  </joint>

  <!-- Leg 4: Mid-Back Right -->
  <link name="coxa_4">
    <inertial>
      <origin xyz="0.025 0 0" rpy="0 0 0"/>
      <mass value="0.1"/>
      <inertia ixx="0.00005" ixy="0" ixz="0" iyy="0.00005" iyz="0" izz="0.00001"/>
    </inertial>
    <visual>
      <origin xyz="0.025 0 0" rpy="0 0 0"/>
      <geometry>
        <box size="0.05 0.02 0.02"/>
      </geometry>
      <material name="leg_color"/>
    </visual>
    <collision>
      <origin xyz="0.025 0 0" rpy="0 0 0"/>
      <geometry>
        <box size="0.05 0.02 0.02"/>
      </geometry>
    </collision>
  </link>

  <joint name="coxa_4" type="revolute">
    <parent link="torso"/>
    <child link="coxa_4"/>
    <origin xyz="-0.02 -0.075 0" rpy="0 0 0"/>
    <axis xyz="0 0 1"/>
    <limit lower="-0.785" upper="0.785" effort="10.0" velocity="5.0"/>
    <dynamics damping="0.5" friction="0.1"/>
  </joint>

  <link name="femur_4">
    <inertial>
      <origin xyz="0 0 -0.05" rpy="0 0 0"/>
      <mass value="0.08"/>
      <inertia ixx="0.00008" ixy="0" ixz="0" iyy="0.00008" iyz="0" izz="0.00001"/>
    </inertial>
    <visual>
      <origin xyz="0 0 -0.05" rpy="0 0 0"/>
      <geometry>
        <box size="0.015 0.015 0.10"/>
      </geometry>
      <material name="leg_color"/>
    </visual>
    <collision>
      <origin xyz="0 0 -0.05" rpy="0 0 0"/>
      <geometry>
        <box size="0.015 0.015 0.10"/>
      </geometry>
    </collision>
  </link>

  <joint name="femur_4" type="revolute">
    <parent link="coxa_4"/>
    <child link="femur_4"/>
    <origin xyz="0.05 0 0" rpy="0 0 0"/>
    <axis xyz="0 1 0"/>
    <limit lower="-1.57" upper="1.57" effort="10.0" velocity="5.0"/>
    <dynamics damping="0.5" friction="0.1"/>
  </joint>

  <link name="tibia_4">
    <inertial>
      <origin xyz="0 0 -0.06" rpy="0 0 0"/>
      <mass value="0.06"/>
      <inertia ixx="0.00007" ixy="0" ixz="0" iyy="0.00007" iyz="0" izz="0.00001"/>
    </inertial>
    <visual>
      <origin xyz="0 0 -0.06" rpy="0 0 0"/>
      <geometry>
        <box size="0.012 0.012 0.12"/>
      </geometry>
      <material name="leg_color"/>
    </visual>
    <collision>
      <origin xyz="0 0 -0.06" rpy="0 0 0"/>
      <geometry>
        <box size="0.012 0.012 0.12"/>
      </geometry>
    </collision>
  </link>

  <joint name="tibia_4" type="revolute">
    <parent link="femur_4"/>
    <child link="tibia_4"/>
    <origin xyz="0 0 -0.10" rpy="0 0 0"/>
    <axis xyz="0 1 0"/>
    <limit lower="-2.356" upper="0.0" effort="10.0" velocity="5.0"/>
    <dynamics damping="0.5" friction="0.1"/>
  </joint>

  <link name="foot_4">
    <inertial>
      <mass value="0.02"/>
      <inertia ixx="0.00001" ixy="0" ixz="0" iyy="0.00001" iyz="0" izz="0.00001"/>
    </inertial>
    <visual>
      <geometry>
        <sphere radius="0.015"/>
      </geometry>
      <material name="foot_color"/>
    </visual>
    <collision>
      <geometry>
        <sphere radius="0.015"/>
      </geometry>
    </collision>
  </link>

  <joint name="foot_4" type="fixed">
    <parent link="tibia_4"/>
    <child link="foot_4"/>
    <origin xyz="0 0 -0.12" rpy="0 0 0"/>
  </joint>

  <!-- Leg 5: Mid-Back Left -->
  <link name="coxa_5">
    <inertial>
      <origin xyz="0.025 0 0" rpy="0 0 0"/>
      <mass value="0.1"/>
      <inertia ixx="0.00005" ixy="0" ixz="0" iyy="0.00005" iyz="0" izz="0.00001"/>
    </inertial>
    <visual>
      <origin xyz="0.025 0 0" rpy="0 0 0"/>
      <geometry>
        <box size="0.05 0.02 0.02"/>
      </geometry>
      <material name="leg_color"/>
    </visual>
    <collision>
      <origin xyz="0.025 0 0" rpy="0 0 0"/>
      <geometry>
        <box size="0.05 0.02 0.02"/>
      </geometry>
    </collision>
  </link>

  <joint name="coxa_5" type="revolute">
    <parent link="torso"/>
    <child link="coxa_5"/>
    <origin xyz="-0.02 0.075 0" rpy="0 0 0"/>
    <axis xyz="0 0 1"/>
    <limit lower="-0.785" upper="0.785" effort="10.0" velocity="5.0"/>
    <dynamics damping="0.5" friction="0.1"/>
  </joint>

  <link name="femur_5">
    <inertial>
      <origin xyz="0 0 -0.05" rpy="0 0 0"/>
      <mass value="0.08"/>
      <inertia ixx="0.00008" ixy="0" ixz="0" iyy="0.00008" iyz="0" izz="0.00001"/>
    </inertial>
    <visual>
      <origin xyz="0 0 -0.05" rpy="0 0 0"/>
      <geometry>
        <box size="0.015 0.015 0.10"/>
      </geometry>
      <material name="leg_color"/>
    </visual>
    <collision>
      <origin xyz="0 0 -0.05" rpy="0 0 0"/>
      <geometry>
        <box size="0.015 0.015 0.10"/>
      </geometry>
    </collision>
  </link>

  <joint name="femur_5" type="revolute">
    <parent link="coxa_5"/>
    <child link="femur_5"/>
    <origin xyz="0.05 0 0" rpy="0 0 0"/>
    <axis xyz="0 1 0"/>
    <limit lower="-1.57" upper="1.57" effort="10.0" velocity="5.0"/>
    <dynamics damping="0.5" friction="0.1"/>
  </joint>

  <link name="tibia_5">
    <inertial>
      <origin xyz="0 0 -0.06" rpy="0 0 0"/>
      <mass value="0.06"/>
      <inertia ixx="0.00007" ixy="0" ixz="0" iyy="0.00007" iyz="0" izz="0.00001"/>
    </inertial>
    <visual>
      <origin xyz="0 0 -0.06" rpy="0 0 0"/>
      <geometry>
        <box size="0.012 0.012 0.12"/>
      </geometry>
      <material name="leg_color"/>
    </visual>
    <collision>
      <origin xyz="0 0 -0.06" rpy="0 0 0"/>
      <geometry>
        <box size="0.012 0.012 0.12"/>
      </geometry>
    </collision>
  </link>

  <joint name="tibia_5" type="revolute">
    <parent link="femur_5"/>
    <child link="tibia_5"/>
    <origin xyz="0 0 -0.10" rpy="0 0 0"/>
    <axis xyz="0 1 0"/>
    <limit lower="-2.356" upper="0.0" effort="10.0" velocity="5.0"/>
    <dynamics damping="0.5" friction="0.1"/>
  </joint>

  <link name="foot_5">
    <inertial>
      <mass value="0.02"/>
      <inertia ixx="0.00001" ixy="0" ixz="0" iyy="0.00001" iyz="0" izz="0.00001"/>
    </inertial>
    <visual>
      <geometry>
        <sphere radius="0.015"/>
      </geometry>
      <material name="foot_color"/>
    </visual>
    <collision>
      <geometry>
        <sphere radius="0.015"/>
      </geometry>
    </collision>
  </link>

  <joint name="foot_5" type="fixed">
    <parent link="tibia_5"/>
    <child link="foot_5"/>
    <origin xyz="0 0 -0.12" rpy="0 0 0"/>
  </joint>

  <!-- Leg 6: Back Right -->
  <link name="coxa_6">
    <inertial>
      <origin xyz="0.025 0 0" rpy="0 0 0"/>
      <mass value="0.1"/>
      <inertia ixx="0.00005" ixy="0" ixz="0" iyy="0.00005" iyz="0" izz="0.00001"/>
    </inertial>
    <visual>
      <origin xyz="0.025 0 0" rpy="0 0 0"/>
      <geometry>
        <box size="0.05 0.02 0.02"/>
      </geometry>
      <material name="leg_color"/>
    </visual>
    <collision>
      <origin xyz="0.025 0 0" rpy="0 0 0"/>
      <geometry>
        <box size="0.05 0.02 0.02"/>
      </geometry>
    </collision>
  </link>

  <joint name="coxa_6" type="revolute">
    <parent link="torso"/>
    <child link="coxa_6"/>
    <origin xyz="-0.08 -0.06 0" rpy="0 0 0"/>
    <axis xyz="0 0 1"/>
    <limit lower="-0.785" upper="0.785" effort="10.0" velocity="5.0"/>
    <dynamics damping="0.5" friction="0.1"/>
  </joint>

  <link name="femur_6">
    <inertial>
      <origin xyz="0 0 -0.05" rpy="0 0 0"/>
      <mass value="0.08"/>
      <inertia ixx="0.00008" ixy="0" ixz="0" iyy="0.00008" iyz="0" izz="0.00001"/>
    </inertial>
    <visual>
      <origin xyz="0 0 -0.05" rpy="0 0 0"/>
      <geometry>
        <box size="0.015 0.015 0.10"/>
      </geometry>
      <material name="leg_color"/>
    </visual>
    <collision>
      <origin xyz="0 0 -0.05" rpy="0 0 0"/>
      <geometry>
        <box size="0.015 0.015 0.10"/>
      </geometry>
    </collision>
  </link>

  <joint name="femur_6" type="revolute">
    <parent link="coxa_6"/>
    <child link="femur_6"/>
    <origin xyz="0.05 0 0" rpy="0 0 0"/>
    <axis xyz="0 1 0"/>
    <limit lower="-1.57" upper="1.57" effort="10.0" velocity="5.0"/>
    <dynamics damping="0.5" friction="0.1"/>
  </joint>

  <link name="tibia_6">
    <inertial>
      <origin xyz="0 0 -0.06" rpy="0 0 0"/>
      <mass value="0.06"/>
      <inertia ixx="0.00007" ixy="0" ixz="0" iyy="0.00007" iyz="0" izz="0.00001"/>
    </inertial>
    <visual>
      <origin xyz="0 0 -0.06" rpy="0 0 0"/>
      <geometry>
        <box size="0.012 0.012 0.12"/>
      </geometry>
      <material name="leg_color"/>
    </visual>
    <collision>
      <origin xyz="0 0 -0.06" rpy="0 0 0"/>
      <geometry>
        <box size="0.012 0.012 0.12"/>
      </geometry>
    </collision>
  </link>

  <joint name="tibia_6" type="revolute">
    <parent link="femur_6"/>
    <child link="tibia_6"/>
    <origin xyz="0 0 -0.10" rpy="0 0 0"/>
    <axis xyz="0 1 0"/>
    <limit lower="-2.356" upper="0.0" effort="10.0" velocity="5.0"/>
    <dynamics damping="0.5" friction="0.1"/>
  </joint>

  <link name="foot_6">
    <inertial>
      <mass value="0.02"/>
      <inertia ixx="0.00001" ixy="0" ixz="0" iyy="0.00001" iyz="0" izz="0.00001"/>
    </inertial>
    <visual>
      <geometry>
        <sphere radius="0.015"/>
      </geometry>
      <material name="foot_color"/>
    </visual>
    <collision>
      <geometry>
        <sphere radius="0.015"/>
      </geometry>
    </collision>
  </link>

  <joint name="foot_6" type="fixed">
    <parent link="tibia_6"/>
    <child link="foot_6"/>
    <origin xyz="0 0 -0.12" rpy="0 0 0"/>
  </joint>

  <!-- Leg 7: Back Left -->
  <link name="coxa_7">
    <inertial>
      <origin xyz="0.025 0 0" rpy="0 0 0"/>
      <mass value="0.1"/>
      <inertia ixx="0.00005" ixy="0" ixz="0" iyy="0.00005" iyz="0" izz="0.00001"/>
    </inertial>
    <visual>
      <origin xyz="0.025 0 0" rpy="0 0 0"/>
      <geometry>
        <box size="0.05 0.02 0.02"/>
      </geometry>
      <material name="leg_color"/>
    </visual>
    <collision>
      <origin xyz="0.025 0 0" rpy="0 0 0"/>
      <geometry>
        <box size="0.05 0.02 0.02"/>
      </geometry>
    </collision>
  </link>

  <joint name="coxa_7" type="revolute">
    <parent link="torso"/>
    <child link="coxa_7"/>
    <origin xyz="-0.08 0.06 0" rpy="0 0 0"/>
    <axis xyz="0 0 1"/>
    <limit lower="-0.785" upper="0.785" effort="10.0" velocity="5.0"/>
    <dynamics damping="0.5" friction="0.1"/>
  </joint>

  <link name="femur_7">
    <inertial>
      <origin xyz="0 0 -0.05" rpy="0 0 0"/>
      <mass value="0.08"/>
      <inertia ixx="0.00008" ixy="0" ixz="0" iyy="0.00008" iyz="0" izz="0.00001"/>
    </inertial>
    <visual>
      <origin xyz="0 0 -0.05" rpy="0 0 0"/>
      <geometry>
        <box size="0.015 0.015 0.10"/>
      </geometry>
      <material name="leg_color"/>
    </visual>
    <collision>
      <origin xyz="0 0 -0.05" rpy="0 0 0"/>
      <geometry>
        <box size="0.015 0.015 0.10"/>
      </geometry>
    </collision>
  </link>

  <joint name="femur_7" type="revolute">
    <parent link="coxa_7"/>
    <child link="femur_7"/>
    <origin xyz="0.05 0 0" rpy="0 0 0"/>
    <axis xyz="0 1 0"/>
    <limit lower="-1.57" upper="1.57" effort="10.0" velocity="5.0"/>
    <dynamics damping="0.5" friction="0.1"/>
  </joint>

  <link name="tibia_7">
    <inertial>
      <origin xyz="0 0 -0.06" rpy="0 0 0"/>
      <mass value="0.06"/>
      <inertia ixx="0.00007" ixy="0" ixz="0" iyy="0.00007" iyz="0" izz="0.00001"/>
    </inertial>
    <visual>
      <origin xyz="0 0 -0.06" rpy="0 0 0"/>
      <geometry>
        <box size="0.012 0.012 0.12"/>
      </geometry>
      <material name="leg_color"/>
    </visual>
    <collision>
      <origin xyz="0 0 -0.06" rpy="0 0 0"/>
      <geometry>
        <box size="0.012 0.012 0.12"/>
      </geometry>
    </collision>
  </link>

  <joint name="tibia_7" type="revolute">
    <parent link="femur_7"/>
    <child link="tibia_7"/>
    <origin xyz="0 0 -0.10" rpy="0 0 0"/>
    <axis xyz="0 1 0"/>
    <limit lower="-2.356" upper="0.0" effort="10.0" velocity="5.0"/>
    <dynamics damping="0.5" friction="0.1"/>
  </joint>

  <link name="foot_7">
    <inertial>
      <mass value="0.02"/>
      <inertia ixx="0.00001" ixy="0" ixz="0" iyy="0.00001" iyz="0" izz="0.00001"/>
    </inertial>
    <visual>
      <geometry>
        <sphere radius="0.015"/>
      </geometry>
      <material name="foot_color"/>
    </visual>
    <collision>
      <geometry>
        <sphere radius="0.015"/>
      </geometry>
    </collision>
  </link>

  <joint name="foot_7" type="fixed">
    <parent link="tibia_7"/>
    <child link="foot_7"/>
    <origin xyz="0 0 -0.12" rpy="0 0 0"/>
  </joint>

</robot>
